<?xml version="1.0"?>

<robot xmlns:xacro="http://ros.org/wiki/xacro" name="i3e-d3_caster">
	<xacro:macro name="i3e-d3_caster" params="prefix radius x y z roll pitch yaw axis_x axis_y axis_z parent_link">

		<link name="${prefix}_base_link">
			<inertial>
				<mass value="0.01" />
				<origin xyz="0 0 0" />
				<inertia ixx="1e-6" ixy="0.0" ixz="0.0" iyy="1e-6" 	iyz="0.0" izz="1e-6" />
			</inertial>
			
			<visual>
				<origin rpy="${PI} 0 0" xyz="${-5/1000} ${-21.5/2000} ${13.5/2000}"/>
				<geometry>
					<mesh filename="package://i3e-d3_description/meshes/caster_base.stl" scale="1 1 1"/> 
				</geometry>

				<material name="gray"/>
			</visual>

			<collision>
				<origin rpy="0 0 0" xyz="0 0 0"/>

				<geometry>
					<box size="${60/1000} ${60/1000} ${13.5/1000}"/>				
				</geometry>
			</collision>
		</link>
		
		<gazebo reference="${prefix}_base_link">
			<material>Gazebo/Grey</material>
			<mu1>0.0</mu1>
			<mu2>0.0</mu2>
			<kp>1000000.0</kp>
			<kd>100.0</kd>
			<minDepth>0.001</minDepth>
			<maxVel>1.0</maxVel>		
		</gazebo>
		
		<joint name="${prefix}_base_joint" type="fixed">
			<parent link="${parent_link}"/>
			<child link="${prefix}_base_link"/>
			<origin rpy="${roll} ${pitch} ${yaw}" xyz="${x} ${y} ${z}"/>
			<axis xyz="0 0 0"/>
		</joint>
				
						
		<link name="${prefix}_rotate_link">
			<inertial>
				<mass value="0.01" />
				<origin xyz="0 0 0" />
				<inertia ixx="1e-6" ixy="0.0" ixz="0.0" iyy="1e-6" iyz="0.0" izz="1e-6" />
			</inertial>
			
			<visual>
				<origin rpy="${PI} 0 ${PI/2}" xyz="0 0 ${10/1000}"/>
				<geometry>
					<mesh filename="package://i3e-d3_description/meshes/caster_rot.stl" scale="1 1 1"/> 
				</geometry>

				<material name="gray"/>
			</visual>
			
			<collision>
				<origin rpy="0 0 0" xyz="0 0 0"/>
				<geometry>
					<cylinder length="${23/1000}" radius="${21.5/1000}"/>
				</geometry>
			</collision>
		</link>
		
		<gazebo reference="${prefix}_rotate_link">
			<material>Gazebo/Grey</material>
			<mu1>0.0</mu1>
			<mu2>0.0</mu2>
			<kp>1000000.0</kp>
			<kd>100.0</kd>
			<minDepth>0.001</minDepth>
			<maxVel>1.0</maxVel>			
		</gazebo>
				
		<joint name="${prefix}_base_rotate_joint" type="continuous">
			<parent link="${prefix}_base_link"/>
			<child link="${prefix}_rotate_link"/>
			<origin rpy="0 0 0" xyz="0.0 0.0 ${-37/2000}"/>
			<axis xyz="0 0 1"/>
		</joint>						
									
		<link name="${prefix}_wheel_link">
			<inertial>
				<mass value="0.01" />
				<origin xyz="0 0 0" />
				<inertia ixx="1e-6" ixy="0.0" ixz="0.0" iyy="1e-6" iyz="0.0" izz="1e-6" />
			</inertial>
			
			<visual>
				<origin rpy="${PI/2} 0 0" xyz="0 0 0"/>
				<geometry>
					<sphere radius="${35/2000}"/>				
				</geometry>
				
				<material name="yellow"/>
			</visual>
			
			<collision>
				<origin rpy="${PI/2} 0 0" xyz="0 0 0"/>

				<geometry>
					<sphere radius="${35/2000}"/>
				</geometry>
			</collision>	
		</link>
		
		<gazebo reference="${prefix}_wheel_link">
			<material>Gazebo/Yellow</material>
			<mu1>0.0</mu1>
			<mu2>0.0</mu2>
			<kp>1000000.0</kp>
			<kd>100.0</kd>
			<minDepth>0.001</minDepth>
			<maxVel>1.0</maxVel>
		</gazebo>
		
		<joint name="${prefix}_rotate_wheel_joint" type="continuous">
			<parent link="${prefix}_rotate_link"/>
			<child link="${prefix}_wheel_link"/>
			<origin rpy="0 0 0" xyz="${-14.632/1000} 0.0 ${-23/2000}"/>
			<axis xyz="0.577350269 0.577350269 0.577350269"/>
		</joint>	

	</xacro:macro>  
</robot>

