<?xml version="1.0"?>
<robot name="i3e-d3_head" xmlns:xacro="http://www.ros.org/wiki/xacro">
  
  <xacro:macro name="i3e-d3_head" params="*joint_pose">

    <xacro:macro name="TransmissionServo" params="joint n">
        <transmission name="tran_${n}">
        <type>transmission_interface/SimpleTransmission</type>
        <joint name="${joint}">
            <hardwareInterface>hardware_interface/PositionJointInterface</hardwareInterface>
        </joint>
        <actuator name="servo_${n}">
            <hardwareInterface>hardware_interface/PositionJointInterface</hardwareInterface>
            <mechanicalReduction>1</mechanicalReduction>
        </actuator>
        </transmission>
    </xacro:macro>

    <link name="motor_neck_link">
        <visual>
            <origin xyz="0.0 0.0 0.0" rpy="0.0 0.0 ${PI/2}"/>
            <geometry>
                <mesh filename="package://i3e-d3_description/meshes/servo.stl"/>
            </geometry>
            <material name="dark_gray"/>
        </visual>
        <collision>
            <origin xyz="0.0 0.0 0.0" rpy="0.0 0.0 ${PI/2}"/>
            <geometry>
                <mesh filename="package://i3e-d3_description/meshes/servo.stl"/>
            </geometry>
        </collision>
        <inertial>
            <origin xyz="0.0 0.0 0.0" rpy="0.0 0.0 ${PI/2}"/>
                <mass value="0.001"/>
                <inertia 
                    ixx="1e-6" ixy="0.0" ixz="0.0" 
                    iyy="1e-6" iyz="0.0" 
                    izz="1e-6"/>
        </inertial>   
    </link>

    <joint name="motor_neck_joint" type="fixed">
        <parent link="base_link"/>
        <child link="motor_neck_link"/>
        <xacro:insert_block name="joint_pose"/>
    </joint>

    <link name="neck_link">
        <visual>
            <origin xyz="0.0 0.0 0.0" rpy="0.0 0.0 0.0"/>
            <geometry>
                <mesh filename="package://i3e-d3_description/meshes/neck.stl"/>
            </geometry>
            <material name="gray"/>
        </visual>
        <collision>
            <origin xyz="0.0 0.0 0.0" rpy="0.0 0.0 0.0"/>
            <geometry>
                <mesh filename="package://i3e-d3_description/meshes/neck.stl"/>
            </geometry>
        </collision>
        <inertial>
            <origin xyz="0.045 0.0 0.1" rpy="0.0 0.0 0.0"/>
                <mass value="0.165"/>
                <inertia 
                    ixx="4.755e-4" ixy="1.448e-7" ixz="-2.282e-4" 
                    iyy="6.841e-4" iyz="8.589e-8" 
                    izz="3.525e-4"/>
        </inertial>
        
    </link>

    <joint name="neck_joint" type="revolute">
        <parent link="motor_neck_link"/>
        <child link="neck_link"/>
        <axis xyz="0 0 1"/>
        <limit lower="-1.5707" upper="1.5707" effort="0.8" velocity="0.5"/>
        <origin xyz="0.0 0.0 0.016" rpy="0.0 0.0 0.0"/>
    </joint>

    <xacro:TransmissionServo n="neck" joint="neck_joint" />

    <link name="motor_head_link">
        <visual>
            <origin xyz="0.0 0.0 0.0" rpy="${PI/2} ${-PI/2} 0.0"/>
            <geometry>
                <mesh filename="package://i3e-d3_description/meshes/servo.stl"/>
            </geometry>
            <material name="dark_gray"/>
        </visual>
        <collision>
            <origin xyz="0.0 0.0 0.0" rpy="${PI/2} ${-PI/2} 0.0"/>
            <geometry>
                <mesh filename="package://i3e-d3_description/meshes/servo.stl"/>
            </geometry>
        </collision>
        <inertial>
            <origin xyz="0.0 0.0 0.0" rpy="${PI/2} ${-PI/2} 0.0"/>
                <mass value="0.001"/>
                <inertia 
                    ixx="1e-6" ixy="0.0" ixz="0.0" 
                    iyy="1e-6" iyz="0.0" 
                    izz="1e-6"/>
        </inertial>
    </link>

    <joint name="head_joint" type="revolute">
        <origin xyz="0.117 -0.0085 0.142" rpy="0.0 0.0 0.0"/>
        <parent link="neck_link"/>
        <child link="motor_head_link"/>
        <axis xyz="0 -1 0"/>
        <limit lower="-0.2618" upper="0.2618" effort="0.8" velocity="0.5"/>
    </joint>

    <xacro:TransmissionServo n="head" joint="head_joint" />

    <link name="face_link">
        <visual>
            <origin xyz="0.0 0.0 0.0" rpy="0.0 0.0 0.0"/>
            <geometry>
                <mesh filename="package://i3e-d3_description/meshes/face.stl"/>
            </geometry>
            <material name="gray"/>
        </visual>
        <inertial>
            <origin xyz="0.01 0.004 -0.004" rpy="0.0 0.0 0.0"/>
                <mass value="0.259"/>
                <inertia 
                    ixx="7.966e-4" ixy="-1.019e-7" ixz="9.196e-6" 
                    iyy="5.993e-4" iyz="7.634e-8" 
                    izz="3.527e-4"/>
        </inertial>
        
    </link>

    <joint name="motor_head_joint" type="fixed">
        <origin xyz="0.0475 0.005 -0.012" rpy="0.0 0.0 0.0"/>
        <child link="face_link"/>
        <parent link="motor_head_link"/>
    </joint>

    <link name="display_link">
        <visual>
            <origin xyz="0.0 0.0 0.0" rpy="0.0 0.0 ${PI}"/>
            <geometry>
                <mesh filename="package://i3e-d3_description/meshes/LEDs_face.stl"/>
            </geometry>
            <material name="white"/>
        </visual>
        <inertial>
            <origin xyz="0.0 0.0 0.0" rpy="0.0 0.0 ${PI}"/>
                <mass value="0.001"/>
                <inertia 
                    ixx="1e-6" ixy="0.0" ixz="0.0" 
                    iyy="1e-6" iyz="0.0" 
                    izz="1e-6"/>
        </inertial>
        
    </link>

    <joint name="display_joint" type="fixed">
        <origin xyz="0.018 0.004 -0.0046" rpy="0.0 0.0 0.0"/>
        <child link="display_link"/>
        <parent link="face_link"/>
    </joint>

    <link name="head_cover_link">
        <visual>
            <origin xyz="0.0 0.0 0.0" rpy="0.0 0.0 0.0"/>
            <geometry>
                <mesh filename="package://i3e-d3_description/meshes/head_cover.stl"/>
            </geometry>
            <material name="blue"/>
        </visual>
        <collision>
            <origin xyz="-0.012 0.0 -0.008" rpy="0.0 0.0 0.0"/>
            <geometry>
                <box size="0.105 0.130 0.170"/>
            </geometry>
        </collision>
        <inertial>
            <origin xyz="0.0 0.0 0.0" rpy="0.0 0.0 0.0"/>
                <mass value="0.252"/>
                <inertia 
                    ixx="1.463e-3" ixy="0.0" ixz="1.598e-4" 
                    iyy="1.046e-3" iyz="0.0" 
                    izz="8.181e-4"/>
        </inertial>
        
    </link>

    <joint name="head_cover_joint" type="fixed">
        <origin xyz="-0.011 0.004 0.009" rpy="0.0 0.0 0.0"/>
        <child link="head_cover_link"/>
        <parent link="face_link"/>
    </joint>

  </xacro:macro>

</robot>
